{"version":3,"sources":["../../Promise/test6.js"],"names":["throwError","value","Error","badMain","onRejected","Promise","resolve","then","goodMain","catch","err","console","log"],"mappings":";;AAAA,SAASA,UAAT,CAAoBC,KAApB,EAA2B;AACzB;AACA,QAAM,IAAIC,KAAJ,CAAU,IAAV,CAAN;AACD;;AAED;AACA,SAASC,OAAT,CAAiBC,UAAjB,EAA6B;AAC3B,SAAOC,QAAQC,OAAR,CAAgB,EAAhB,EAAoBC,IAApB,CAAyBP,UAAzB,EAAqCI,UAArC,CAAP;AACD;;AAED;AACA,SAASI,QAAT,CAAkBJ,UAAlB,EAA8B;AAC5B,SAAOC,QAAQC,OAAR,CAAgB,EAAhB,EAAoBC,IAApB,CAAyBP,UAAzB,EAAqCS,KAArC,CAA2CL,UAA3C,CAAP;AACD;;AAED;AACA;AACA;AACA;AACAI,SAAS,UAASE,GAAT,EAAc;AACrBC,UAAQC,GAAR,CAAYF,GAAZ;AACAC,UAAQC,GAAR,CAAY,MAAZ;AACD,CAHD","file":"test6.js","sourcesContent":["function throwError(value) {\n  // 抛出异常\n  throw new Error('33');\n}\n\n// <1> onRejected不会被调用\nfunction badMain(onRejected) {\n  return Promise.resolve(42).then(throwError, onRejected);\n}\n\n// <2> 有异常发生时onRejected会被调用\nfunction goodMain(onRejected) {\n  return Promise.resolve(42).then(throwError).catch(onRejected);\n}\n\n// 运行示例\n// badMain(function() {\n//   console.log('BAD');\n// });\ngoodMain(function(err) {\n  console.log(err);\n  console.log('GOOD');\n});"]}